Workbook

Sheet Project Overview
A1: Senior SQL Practice Project: Global Logistics Data Warehouse
A3: Project Type | B3: Self-directed portfolio and interview practice project
A4: Target Role | B4: Senior Azure Data Engineer, approximately 6-year capability level
A5: Business Scenario | B5: Build a SQL data warehouse for global logistics orders, shipments, customer history, revenue, delay analysis, incremental loading, performance tuning, and reconciliation.
A6: Practice Commitment | B6: 2 to 3 hours per working day
A7: Database Recommendation | B7: SQL Server Developer Edition or Azure SQL Database
A8: Delivery Method | B8: Complete phases sequentially; record evidence, test results, and design decisions.
A9: Important Resume Note | B9: Describe this as a personal or portfolio project unless implemented for a real client. Do not present synthetic volumes or outcomes as production facts.
A12: Business Outcomes
A13: • Design a defensible star schema with explicit fact-table grain.
A14: • Implement dimensions and facts with auditability and unknown-member handling.
A15: • Implement SCD Type 2 customer history.
A16: • Produce revenue, growth, ranking, delivery-delay, and trend analytics.
A17: • Build restartable incremental loading using a watermark and batch-control pattern.
A18: • Investigate and optimize large-table query performance.
A19: • Reconcile revenue and document root-cause evidence.
A20: • Package scripts, tests, diagrams, runbooks, and portfolio evidence.
A23: Workbook Guide
A24: Requirements | B24: Detailed business, functional, non-functional, data, and acceptance requirements.
A25: Task Plan | B25: Small implementation tasks with planned hours, dependencies, deliverables, status, and completion.
A26: Daily Plan | B26: A formula-driven 2 to 3 hour working-day schedule.
A27: Test Cases | B27: Functional, data-quality, reconciliation, failure-recovery, and performance tests.
A28: Data Dictionary | B28: Source and warehouse object/column definitions.
A29: Dashboard | B29: Overall progress, planned hours, test progress, and phase charts.
A30: Risks & Decisions | B30: Architecture risks, mitigations, assumptions, and decision log.
A31: Resume Notes | B31: Honest portfolio wording and interview discussion points.

Sheet Requirements
A1: Detailed Requirements Register
A3: Requirement ID | B3: Phase | C3: Category | D3: Requirement | E3: Detailed Description | F3: Priority | G3: Acceptance Criteria | H3: Deliverable
A4: REQ-001 | B4: 1 - Warehouse Modeling | C4: Business | D4: Confirm analytical scope | E4: Define revenue, customer, product, location, order, shipment and calendar analysis required by stakeholders. | F4: Must | G4: Scope explicitly lists included metrics and excluded scenarios. | H4: Scope document
A5: REQ-002 | B5: 1 - Warehouse Modeling | C5: Modeling | D5: Declare FactOrders grain | E5: Define one row per order line, represented by OrderID plus OrderLineNumber. ProductID alone is insufficient if the same product can appear more than once in an order. | F5: Must | G5: Grain statement is written before table design and every fact column conforms to it. | H5: Grain statement
A6: REQ-003 | B6: 1 - Warehouse Modeling | C6: Modeling | D6: Declare FactShipment grain | E6: Define one row per shipment event or shipment record. Document treatment of split shipments and multiple delivery attempts. | F6: Must | G6: Grain and business key are unambiguous. | H6: Shipment grain statement
A7: REQ-004 | B7: 1 - Warehouse Modeling | C7: Modeling | D7: Design star schema | E7: Create FactOrders, FactShipment, DimCustomer, DimProduct, DimDate and DimLocation relationships. | F7: Must | G7: Diagram shows PK/FK relationships and no unresolved many-to-many relationship. | H7: ERD/star schema
A8: REQ-005 | B8: 1 - Warehouse Modeling | C8: Keys | D8: Use surrogate keys | E8: Use integer/bigint surrogate keys for warehouse dimensions while retaining source business keys. | F8: Must | G8: Facts reference surrogate keys; source keys remain available for traceability. | H8: DDL design
A9: REQ-006 | B9: 1 - Warehouse Modeling | C9: Keys | D9: Create unknown members | E9: Insert key 0 or -1 rows for unknown customer, product, date or location where applicable. | F9: Must | G9: Unmatched source rows load without null dimension foreign keys and are reportable. | H9: Unknown-member script
A10: REQ-007 | B10: 1 - Warehouse Modeling | C10: Data | D10: Define additive measures | E10: Store Quantity, GrossAmount, DiscountAmount, NetAmount, CostAmount and FreightAllocatedAmount at the declared grain where available. | F10: Should | G10: Each measure has a definition and aggregation behavior. | H10: Measure catalogue
A11: REQ-008 | B11: 1 - Warehouse Modeling | C11: Audit | D11: Add audit columns | E11: Include BatchID, SourceSystem, SourceModifiedDate, InsertedDateTime and UpdatedDateTime where applicable. | F11: Must | G11: Every loaded row can be traced to a batch and source. | H11: Audit-column standard
A12: REQ-009 | B12: 1 - Warehouse Modeling | C12: Modeling | D12: Role-playing date dimensions | E12: Represent OrderDate, ShipmentDate and DeliveryDate through separate foreign keys to DimDate. | F12: Must | G12: Date roles are clear and joins return correct calendar attributes. | H12: Date-key design
A13: REQ-010 | B13: 1 - Warehouse Modeling | C13: Data Quality | D13: Enforce key integrity | E13: Define PK, unique business-key constraints where practical, and FK strategy. | F13: Should | G13: Duplicate dimension business keys and orphan fact keys are detected. | H13: Constraint script
A14: REQ-011 | B14: 2 - SCD Type 2 | C14: History | D14: Track customer changes | E14: Track City, Country and CustomerType changes while preserving prior values. | F14: Must | G14: A changed tracked attribute expires the old row and creates one new current row. | H14: SCD procedure
... A76: REQ-073 | B76: 10 - Packaging & Portfolio | C76: Interview | D76: Prepare design defense | E76: Explain trade-offs, failure recovery, data quality, performance, and alternative approaches. | F76: Must | G76: A concise walkthrough and deep-dive answers are prepared. | H76: Interview notes

Sheet Task Plan
A1: Granular Task Plan and Effort Estimate
A3: Task ID | B3: Req ID | C3: Phase | D3: Category | E3: Small Task | F3: Implementation Notes | G3: Priority | H3: Planned Hours | I3: Dependency | J3: Deliverable / Evidence | K3: Status | L3: Completion % | M3: Actual Hours | N3: Comments
A4: TSK-001 | B4: REQ-001 | C4: 1 - Warehouse Modeling | D4: Business | E4: Analyze and document - Confirm analytical scope | F4: Define revenue, customer, product, location, order, shipment and calendar analysis required by stakeholders. | G4: Must | H4: 1 | J4: Analyze and document: Confirm analytical scope | K4: Not Started | L4: 0
A5: TSK-002 | B5: REQ-001 | C5: 1 - Warehouse Modeling | D5: Business | E5: Design approach - Confirm analytical scope | F5: Define revenue, customer, product, location, order, shipment and calendar analysis required by stakeholders. | G5: Must | H5: 0.5 | I5: TSK-001 | J5: Design approach: Confirm analytical scope | K5: Not Started | L5: 0
A6: TSK-003 | B6: REQ-001 | C6: 1 - Warehouse Modeling | D6: Business | E6: Implement SQL or artifact - Confirm analytical scope | F6: Define revenue, customer, product, location, order, shipment and calendar analysis required by stakeholders. | G6: Must | H6: 1 | I6: TSK-002 | J6: Scope document | K6: Not Started | L6: 0
A7: TSK-004 | B7: REQ-001 | C7: 1 - Warehouse Modeling | D7: Business | E7: Create and execute tests - Confirm analytical scope | F7: Define revenue, customer, product, location, order, shipment and calendar analysis required by stakeholders. | G7: Must | H7: 1 | I7: TSK-003 | J7: Create and execute tests: Confirm analytical scope | K7: Not Started | L7: 0
A8: TSK-005 | B8: REQ-001 | C8: 1 - Warehouse Modeling | D8: Business | E8: Record evidence and decisions - Confirm analytical scope | F8: Define revenue, customer, product, location, order, shipment and calendar analysis required by stakeholders. | G8: Must | H8: 0.5 | I8: TSK-004 | J8: Record evidence and decisions: Confirm analytical scope | K8: Not Started | L8: 0
A9: TSK-006 | B9: REQ-002 | C9: 1 - Warehouse Modeling | D9: Modeling | E9: Analyze and document - Declare FactOrders grain | F9: Define one row per order line, represented by OrderID plus OrderLineNumber. ProductID alone is insufficient if the same product can appear more than once in an order. | G9: Must | H9: 0.5 | I9: TSK-005 | J9: Analyze and document: Declare FactOrders grain | K9: Not Started | L9: 0
A10: TSK-007 | B10: REQ-002 | C10: 1 - Warehouse Modeling | D10: Modeling | E10: Design approach - Declare FactOrders grain | F10: Define one row per order line, represented by OrderID plus OrderLineNumber. ProductID alone is insufficient if the same product can appear more than once in an order. | G10: Must | H10: 0.5 | I10: TSK-006 | J10: Design approach: Declare FactOrders grain | K10: Not Started | L10: 0
A11: TSK-008 | B11: REQ-002 | C11: 1 - Warehouse Modeling | D11: Modeling | E11: Implement SQL or artifact - Declare FactOrders grain | F11: Define one row per order line, represented by OrderID plus OrderLineNumber. ProductID alone is insufficient if the same product can appear more than once in an order. | G11: Must | H11: 1 | I11: TSK-007 | J11: Grain statement | K11: Not Started | L11: 0
A12: TSK-009 | B12: REQ-002 | C12: 1 - Warehouse Modeling | D12: Modeling | E12: Create and execute tests - Declare FactOrders grain | F12: Define one row per order line, represented by OrderID plus OrderLineNumber. ProductID alone is insufficient if the same product can appear more than once in an order. | G12: Must | H12: 1 | I12: TSK-008 | J12: Create and execute tests: Declare FactOrders grain | K12: Not Started | L12: 0
A13: TSK-010 | B13: REQ-002 | C13: 1 - Warehouse Modeling | D13: Modeling | E13: Record evidence and decisions - Declare FactOrders grain | F13: Define one row per order line, represented by OrderID plus OrderLineNumber. ProductID alone is insufficient if the same product can appear more than once in an order. | G13: Must | H13: 0.5 | I13: TSK-009 | J13: Record evidence and decisions: Declare FactOrders grain | K13: Not Started | L13: 0
A14: TSK-011 | B14: REQ-003 | C14: 1 - Warehouse Modeling | D14: Modeling | E14: Analyze and document - Declare FactShipment grain | F14: Define one row per shipment event or shipment record. Document treatment of split shipments and multiple delivery attempts. | G14: Must | H14: 1 | I14: TSK-010 | J14: Analyze and document: Declare FactShipment grain | K14: Not Started | L14: 0
A15: TSK-012 | B15: REQ-003 | C15: 1 - Warehouse Modeling | D15: Modeling | E15: Design approach - Declare FactShipment grain | F15: Define one row per shipment event or shipment record. Document treatment of split shipments and multiple delivery attempts. | G15: Must | H15: 1 | I15: TSK-011 | J15: Design approach: Declare FactShipment grain | K15: Not Started | L15: 0
A16: TSK-013 | B16: REQ-003 | C16: 1 - Warehouse Modeling | D16: Modeling | E16: Implement SQL or artifact - Declare FactShipment grain | F16: Define one row per shipment event or shipment record. Document treatment of split shipments and multiple delivery attempts. | G16: Must | H16: 2 | I16: TSK-012 | J16: Shipment grain statement | K16: Not Started | L16: 0
... A368: TSK-365 | B368: REQ-073 | C368: 10 - Packaging & Portfolio | D368: Interview | E368: Record evidence and decisions - Prepare design defense | F368: Explain trade-offs, failure recovery, data quality, performance, and alternative approaches. | G368: Must | H368: 0.5 | I368: TSK-364 | J368: Record evidence and decisions: Prepare design defense | K368: Not Started | L368: 0

Sheet Daily Plan
A1: Daily Study Plan: 2 to 3 Hours per Working Day
A3: Day # | B3: Planned Date | C3: Daily Capacity | D3: Task ID | E3: Phase | F3: Small Task | G3: Allocated Hours | H3: Task Status | I3: Task Completion % | J3: Daily Planned Total | K3: Notes
A4: 1 | B4: 46266 | C4: 3 | D4: TSK-001 | E4: 1 - Warehouse Modeling | F4: Analyze and document - Confirm analytical scope | G4: 1 | H4: =IFERROR(_xlfn.SINGLE(_xlfn.XLOOKUP(D4, 'Task Plan'!$A:$A, 'Task Plan'!$K:$K)), "") -> Not Started | I4: =IFERROR(_xlfn.SINGLE(_xlfn.XLOOKUP(D4, 'Task Plan'!$A:$A, 'Task Plan'!$L:$L)), 0) -> 0 | J4: =SUMIF($A:$A,A4,$G:$G) -> 3
A5: 1 | B5: 46266 | C5: 3 | D5: TSK-002 | E5: 1 - Warehouse Modeling | F5: Design approach - Confirm analytical scope | G5: 0.5 | H5: =IFERROR(_xlfn.SINGLE(_xlfn.XLOOKUP(D5, 'Task Plan'!$A:$A, 'Task Plan'!$K:$K)), "") -> Not Started | I5: =IFERROR(_xlfn.SINGLE(_xlfn.XLOOKUP(D5, 'Task Plan'!$A:$A, 'Task Plan'!$L:$L)), 0) -> 0 | J5: =SUMIF($A:$A,A5,$G:$G) -> 3
A6: 1 | B6: 46266 | C6: 3 | D6: TSK-003 | E6: 1 - Warehouse Modeling | F6: Implement SQL or artifact - Confirm analytical scope | G6: 1 | H6: =IFERROR(_xlfn.SINGLE(_xlfn.XLOOKUP(D6, 'Task Plan'!$A:$A, 'Task Plan'!$K:$K)), "") -> Not Started | I6: =IFERROR(_xlfn.SINGLE(_xlfn.XLOOKUP(D6, 'Task Plan'!$A:$A, 'Task Plan'!$L:$L)), 0) -> 0 | J6: =SUMIF($A:$A,A6,$G:$G) -> 3
A7: 1 | B7: 46266 | C7: 3 | D7: TSK-004 | E7: 1 - Warehouse Modeling | F7: Create and execute tests - Confirm analytical scope | G7: 0.5 | H7: =IFERROR(_xlfn.SINGLE(_xlfn.XLOOKUP(D7, 'Task Plan'!$A:$A, 'Task Plan'!$K:$K)), "") -> Not Started | I7: =IFERROR(_xlfn.SINGLE(_xlfn.XLOOKUP(D7, 'Task Plan'!$A:$A, 'Task Plan'!$L:$L)), 0) -> 0 | J7: =SUMIF($A:$A,A7,$G:$G) -> 3
A8: 2 | B8: 46267 | C8: 2 | D8: TSK-004 | E8: 1 - Warehouse Modeling | F8: Create and execute tests - Confirm analytical scope | G8: 0.5 | H8: =IFERROR(_xlfn.SINGLE(_xlfn.XLOOKUP(D8, 'Task Plan'!$A:$A, 'Task Plan'!$K:$K)), "") -> Not Started | I8: =IFERROR(_xlfn.SINGLE(_xlfn.XLOOKUP(D8, 'Task Plan'!$A:$A, 'Task Plan'!$L:$L)), 0) -> 0 | J8: =SUMIF($A:$A,A8,$G:$G) -> 2
A9: 2 | B9: 46267 | C9: 2 | D9: TSK-005 | E9: 1 - Warehouse Modeling | F9: Record evidence and decisions - Confirm analytical scope | G9: 0.5 | H9: =IFERROR(_xlfn.SINGLE(_xlfn.XLOOKUP(D9, 'Task Plan'!$A:$A, 'Task Plan'!$K:$K)), "") -> Not Started | I9: =IFERROR(_xlfn.SINGLE(_xlfn.XLOOKUP(D9, 'Task Plan'!$A:$A, 'Task Plan'!$L:$L)), 0) -> 0 | J9: =SUMIF($A:$A,A9,$G:$G) -> 2
A10: 2 | B10: 46267 | C10: 2 | D10: TSK-006 | E10: 1 - Warehouse Modeling | F10: Analyze and document - Declare FactOrders grain | G10: 0.5 | H10: =IFERROR(_xlfn.SINGLE(_xlfn.XLOOKUP(D10, 'Task Plan'!$A:$A, 'Task Plan'!$K:$K)), "") -> Not Started | I10: =IFERROR(_xlfn.SINGLE(_xlfn.XLOOKUP(D10, 'Task Plan'!$A:$A, 'Task Plan'!$L:$L)), 0) -> 0 | J10: =SUMIF($A:$A,A10,$G:$G) -> 2
A11: 2 | B11: 46267 | C11: 2 | D11: TSK-007 | E11: 1 - Warehouse Modeling | F11: Design approach - Declare FactOrders grain | G11: 0.5 | H11: =IFERROR(_xlfn.SINGLE(_xlfn.XLOOKUP(D11, 'Task Plan'!$A:$A, 'Task Plan'!$K:$K)), "") -> Not Started | I11: =IFERROR(_xlfn.SINGLE(_xlfn.XLOOKUP(D11, 'Task Plan'!$A:$A, 'Task Plan'!$L:$L)), 0) -> 0 | J11: =SUMIF($A:$A,A11,$G:$G) -> 2
A12: 3 | B12: 46268 | C12: 2.5 | D12: TSK-008 | E12: 1 - Warehouse Modeling | F12: Implement SQL or artifact - Declare FactOrders grain | G12: 1 | H12: =IFERROR(_xlfn.SINGLE(_xlfn.XLOOKUP(D12, 'Task Plan'!$A:$A, 'Task Plan'!$K:$K)), "") -> Not Started | I12: =IFERROR(_xlfn.SINGLE(_xlfn.XLOOKUP(D12, 'Task Plan'!$A:$A, 'Task Plan'!$L:$L)), 0) -> 0 | J12: =SUMIF($A:$A,A12,$G:$G) -> 2.5
A13: 3 | B13: 46268 | C13: 2.5 | D13: TSK-009 | E13: 1 - Warehouse Modeling | F13: Create and execute tests - Declare FactOrders grain | G13: 1 | H13: =IFERROR(_xlfn.SINGLE(_xlfn.XLOOKUP(D13, 'Task Plan'!$A:$A, 'Task Plan'!$K:$K)), "") -> Not Started | I13: =IFERROR(_xlfn.SINGLE(_xlfn.XLOOKUP(D13, 'Task Plan'!$A:$A, 'Task Plan'!$L:$L)), 0) -> 0 | J13: =SUMIF($A:$A,A13,$G:$G) -> 2.5
A14: 3 | B14: 46268 | C14: 2.5 | D14: TSK-010 | E14: 1 - Warehouse Modeling | F14: Record evidence and decisions - Declare FactOrders grain | G14: 0.5 | H14: =IFERROR(_xlfn.SINGLE(_xlfn.XLOOKUP(D14, 'Task Plan'!$A:$A, 'Task Plan'!$K:$K)), "") -> Not Started | I14: =IFERROR(_xlfn.SINGLE(_xlfn.XLOOKUP(D14, 'Task Plan'!$A:$A, 'Task Plan'!$L:$L)), 0) -> 0 | J14: =SUMIF($A:$A,A14,$G:$G) -> 2.5
A15: 4 | B15: 46269 | C15: 3 | D15: TSK-011 | E15: 1 - Warehouse Modeling | F15: Analyze and document - Declare FactShipment grain | G15: 1 | H15: =IFERROR(_xlfn.SINGLE(_xlfn.XLOOKUP(D15, 'Task Plan'!$A:$A, 'Task Plan'!$K:$K)), "") -> Not Started | I15: =IFERROR(_xlfn.SINGLE(_xlfn.XLOOKUP(D15, 'Task Plan'!$A:$A, 'Task Plan'!$L:$L)), 0) -> 0 | J15: =SUMIF($A:$A,A15,$G:$G) -> 3
... A423: 137 | B423: 46456 | C423: 2.5 | D423: TSK-365 | E423: 10 - Packaging & Portfolio | F423: Record evidence and decisions - Prepare design defense | G423: 0.5 | H423: =IFERROR(_xlfn.SINGLE(_xlfn.XLOOKUP(D423, 'Task Plan'!$A:$A, 'Task Plan'!$K:$K)), "") -> Not Started | I423: =IFERROR(_xlfn.SINGLE(_xlfn.XLOOKUP(D423, 'Task Plan'!$A:$A, 'Task Plan'!$L:$L)), 0) -> 0 | J423: =SUMIF($A:$A,A423,$G:$G) -> 1

Sheet Test Cases
A1: Detailed Test Cases and Evidence Tracker
A3: Test Case ID | B3: Phase | C3: Test Area | D3: Scenario | E3: Preconditions / Test Data | F3: Execution Steps | G3: Expected Result | H3: Severity | I3: Status | J3: Actual Result | K3: Evidence Reference | L3: Defect / Notes
A4: TC-001 | B4: 1 - Warehouse Modeling | C4: Business | D4: Confirm analytical scope | E4: Related object for REQ-001 is deployed | F4: Prepare minimum data for Confirm analytical scope; execute relevant SQL; compare actual result with acceptance criteria. | G4: Scope explicitly lists included metrics and excluded scenarios. | H4: Critical | I4: Not Run
A5: TC-002 | B5: 1 - Warehouse Modeling | C5: Modeling | D5: Declare FactOrders grain | E5: Related object for REQ-002 is deployed | F5: Prepare minimum data for Declare FactOrders grain; execute relevant SQL; compare actual result with acceptance criteria. | G5: Grain statement is written before table design and every fact column conforms to it. | H5: Critical | I5: Not Run
A6: TC-003 | B6: 1 - Warehouse Modeling | C6: Modeling | D6: Declare FactShipment grain | E6: Related object for REQ-003 is deployed | F6: Prepare minimum data for Declare FactShipment grain; execute relevant SQL; compare actual result with acceptance criteria. | G6: Grain and business key are unambiguous. | H6: Critical | I6: Not Run
A7: TC-004 | B7: 1 - Warehouse Modeling | C7: Modeling | D7: Design star schema | E7: Related object for REQ-004 is deployed | F7: Prepare minimum data for Design star schema; execute relevant SQL; compare actual result with acceptance criteria. | G7: Diagram shows PK/FK relationships and no unresolved many-to-many relationship. | H7: Critical | I7: Not Run
A8: TC-005 | B8: 1 - Warehouse Modeling | C8: Keys | D8: Use surrogate keys | E8: Related object for REQ-005 is deployed | F8: Prepare minimum data for Use surrogate keys; execute relevant SQL; compare actual result with acceptance criteria. | G8: Facts reference surrogate keys; source keys remain available for traceability. | H8: Critical | I8: Not Run
A9: TC-006 | B9: 1 - Warehouse Modeling | C9: Keys | D9: Create unknown members | E9: Related object for REQ-006 is deployed | F9: Prepare minimum data for Create unknown members; execute relevant SQL; compare actual result with acceptance criteria. | G9: Unmatched source rows load without null dimension foreign keys and are reportable. | H9: Critical | I9: Not Run
A10: TC-007 | B10: 1 - Warehouse Modeling | C10: Data | D10: Define additive measures | E10: Related object for REQ-007 is deployed | F10: Prepare minimum data for Define additive measures; execute relevant SQL; compare actual result with acceptance criteria. | G10: Each measure has a definition and aggregation behavior. | H10: Medium | I10: Not Run
A11: TC-008 | B11: 1 - Warehouse Modeling | C11: Audit | D11: Add audit columns | E11: Related object for REQ-008 is deployed | F11: Prepare minimum data for Add audit columns; execute relevant SQL; compare actual result with acceptance criteria. | G11: Every loaded row can be traced to a batch and source. | H11: Critical | I11: Not Run
A12: TC-009 | B12: 1 - Warehouse Modeling | C12: Modeling | D12: Role-playing date dimensions | E12: Related object for REQ-009 is deployed | F12: Prepare minimum data for Role-playing date dimensions; execute relevant SQL; compare actual result with acceptance criteria. | G12: Date roles are clear and joins return correct calendar attributes. | H12: Critical | I12: Not Run
A13: TC-010 | B13: 1 - Warehouse Modeling | C13: Data Quality | D13: Enforce key integrity | E13: Related object for REQ-010 is deployed | F13: Prepare minimum data for Enforce key integrity; execute relevant SQL; compare actual result with acceptance criteria. | G13: Duplicate dimension business keys and orphan fact keys are detected. | H13: Medium | I13: Not Run
A14: TC-011 | B14: 2 - SCD Type 2 | C14: History | D14: Track customer changes | E14: Related object for REQ-011 is deployed | F14: Prepare minimum data for Track customer changes; execute relevant SQL; compare actual result with acceptance criteria. | G14: A changed tracked attribute expires the old row and creates one new current row. | H14: Critical | I14: Not Run
A15: TC-012 | B15: 2 - SCD Type 2 | C15: History | D15: Ignore non-changing records | E15: Related object for REQ-012 is deployed | F15: Prepare minimum data for Ignore non-changing records; execute relevant SQL; compare actual result with acceptance criteria. | G15: Reprocessing identical source produces no extra versions. | H15: Critical | I15: Not Run
... A91: TC-088 | B91: 9 - Reconciliation & RCA | C91: Rounding | D91: Currency rounding variance | E91: Prepare known rounding differences | F91: Run threshold rule | G91: Difference within tolerance warns/passes per policy; larger difference fails. | H91: High | I91: Not Run

Sheet Data Dictionary
A1: Logical Data Dictionary
A3: Object | B3: Column | C3: Role | D3: Suggested Type | E3: Nullable | F3: Key / Rule | G3: Definition | H3: Example | I3: Notes
A4: DimCustomer | B4: CustomerSK | C4: Surrogate key | D4: BIGINT | E4: No | F4: PK | G4: Warehouse-generated customer version key | H4: 101 | I4: Referenced by facts
A5: DimCustomer | B5: CustomerID | C5: Business key | D5: VARCHAR(50) | E5: No | F5: Indexed | G5: Source customer identifier | H5: C1001 | I5: Retain source key
A6: DimCustomer | B6: CustomerName | C6: Attribute | D6: VARCHAR(200) | E6: No | G6: Customer display name | H6: Contoso Logistics
A7: DimCustomer | B7: Country | C7: SCD2 attribute | D7: VARCHAR(100) | E7: Yes | G7: Customer country for this version | H7: India | I7: Tracked
A8: DimCustomer | B8: City | C8: SCD2 attribute | D8: VARCHAR(100) | E8: Yes | G8: Customer city for this version | H8: Chennai | I8: Tracked
A9: DimCustomer | B9: CustomerType | C9: SCD2 attribute | D9: VARCHAR(50) | E9: Yes | G9: Business classification | H9: Enterprise | I9: Tracked
A10: DimCustomer | B10: EffectiveFrom | C10: History | D10: DATETIME2 | E10: No | G10: Version start time | H10: 2026-09-01 10:00 | I10: Inclusive
A11: DimCustomer | B11: EffectiveTo | C11: History | D11: DATETIME2 | E11: No | G11: Version end time | H11: 9999-12-31 | I11: Convention must be documented
A12: DimCustomer | B12: IsCurrent | C12: History | D12: BIT | E12: No | G12: Current version flag | H12: 1 | I12: One current row per CustomerID
A13: DimProduct | B13: ProductSK | C13: Surrogate key | D13: BIGINT | E13: No | F13: PK | G13: Warehouse product key | H13: 201
A14: DimProduct | B14: ProductID | C14: Business key | D14: VARCHAR(50) | E14: No | F14: Unique current key | G14: Source product identifier | H14: P100
A15: DimProduct | B15: ProductName | C15: Attribute | D15: VARCHAR(200) | E15: No | G15: Product name | H15: Laptop
A16: DimProduct | B16: Category | C16: Attribute | D16: VARCHAR(100) | E16: Yes | G16: Product category | H16: Electronics
A17: DimProduct | B17: CostPrice | C17: Measure-like attribute | D17: DECIMAL(19,4) | E17: Yes | G17: Reference cost; transaction cost is preferable for historical margin | H17: 450.00 | I17: Do not rely on current value for historical fact if price changes
A18: DimProduct | B18: SellingPrice | C18: Measure-like attribute | D18: DECIMAL(19,4) | E18: Yes | G18: Reference selling price | H18: 500.00 | I18: Store actual amount in fact
A19: DimDate | B19: DateSK | C19: Smart key | D19: INT | E19: No | F19: PK | G19: YYYYMMDD date key | H19: 20260901 | I19: Unknown key handled separately
A20: DimDate | B20: FullDate | C20: Date | D20: DATE | E20: No | F20: Unique | G20: Calendar date | H20: 2026-09-01
A21: DimDate | B21: MonthNumber | C21: Calendar | D21: TINYINT | E21: No | G21: Month number | H21: 9
A22: DimDate | B22: MonthName | C22: Calendar | D22: VARCHAR(10) | E22: No | G22: Month name | H22: September
A23: DimDate | B23: QuarterNumber | C23: Calendar | D23: TINYINT | E23: No | G23: Calendar quarter | H23: 3
A24: DimDate | B24: CalendarYear | C24: Calendar | D24: SMALLINT | E24: No | G24: Calendar year | H24: 2026
A25: DimLocation | B25: LocationSK | C25: Surrogate key | D25: BIGINT | E25: No | F25: PK | G25: Warehouse location key | H25: 301
A26: DimLocation | B26: Country | C26: Attribute | D26: VARCHAR(100) | E26: No | G26: Country | H26: India
A27: DimLocation | B27: City | C27: Attribute | D27: VARCHAR(100) | E27: Yes | G27: City | H27: Chennai
A28: FactOrders | B28: OrderID | C28: Degenerate/business key | D28: VARCHAR(50) | E28: No | F28: Business key component | G28: Source order identifier | H28: O50001
A29: FactOrders | B29: OrderLineNumber | C29: Grain key | D29: INT | E29: No | F29: Business key component | G29: Line inside order | H29: 1 | I29: Required for precise grain
A30: FactOrders | B30: CustomerSK | C30: Foreign key | D30: BIGINT | E30: No | F30: FK | G30: Customer version valid for the order | H30: 101
A31: FactOrders | B31: ProductSK | C31: Foreign key | D31: BIGINT | E31: No | F31: FK | G31: Product dimension key | H31: 201
A32: FactOrders | B32: OrderDateSK | C32: Foreign key | D32: INT | E32: No | F32: FK | G32: Order-date role key | H32: 20260901
A33: FactOrders | B33: LocationSK | C33: Foreign key | D33: BIGINT | E33: No | F33: FK | G33: Transaction/customer location key per design | H33: 301
A34: FactOrders | B34: Quantity | C34: Measure | D34: DECIMAL(18,3) | E34: No | F34: Additive | G34: Ordered quantity | H34: 5
A35: FactOrders | B35: GrossAmount | C35: Measure | D35: DECIMAL(19,4) | E35: No | F35: Additive | G35: Amount before adjustments | H35: 2500.00
A36: FactOrders | B36: NetAmount | C36: Measure | D36: DECIMAL(19,4) | E36: No | F36: Additive | G36: Approved revenue expression result | H36: 2400.00 | I36: Definition required
A37: FactOrders | B37: BatchID | C37: Audit | D37: BIGINT | E37: No | G37: Load batch identifier | H37: 9001
A38: FactShipment | B38: ShipmentID | C38: Business key | D38: VARCHAR(50) | E38: No | F38: Business key | G38: Source shipment identifier | H38: S90001
A39: FactShipment | B39: OrderID | C39: Relationship key | D39: VARCHAR(50) | E39: No | G39: Related order identifier | H39: O50001 | I39: Bridge/order-line approach needed for split allocation
A40: FactShipment | B40: ShipmentDateSK | C40: Foreign key | D40: INT | E40: Yes | F40: FK | G40: Shipment date role | H40: 20260902
A41: FactShipment | B41: DeliveryDateSK | C41: Foreign key | D41: INT | E41: Yes | F41: FK | G41: Delivery date role | H41: 20260908 | I41: Null when undelivered
...

Sheet Dashboard
A1: Project Completion Dashboard
A3: Overall KPIs
A4: Total Requirements | B4: =COUNTA(Requirements!A4:A76) -> 73
A5: Total Small Tasks | B5: =COUNTA('Task Plan'!A4:A368) -> 365
A6: Planned Hours | B6: =SUM('Task Plan'!H4:H368) -> 340.5
A7: Actual Hours | B7: =SUM('Task Plan'!M4:M368) -> 0
A8: Task Completion | B8: =IFERROR(SUMPRODUCT('Task Plan'!H4:H368,'Task Plan'!L4:L368)/SUM('Task Plan'!H4:H368),0) -> 0
A9: Tests Passed | B9: =COUNTIF('Test Cases'!I4:I91,"Passed") -> 0
A10: Tests Failed | B10: =COUNTIF('Test Cases'!I4:I91,"Failed") -> 0
A11: Test Pass Rate | B11: =IFERROR(COUNTIF('Test Cases'!I4:I91,"Passed")/COUNTIF('Test Cases'!I4:I91,"<>Not Run"),0) -> 0
A14: Phase | B14: Planned Hours | C14: Completed Weighted Hours | D14: Completion % | E14: Task Count | F14: Completed Tasks
A15: 1 - Warehouse Modeling | B15: =SUMIF('Task Plan'!$C:$C,A15,'Task Plan'!$H:$H) -> 44 | C15: =SUMPRODUCT(('Task Plan'!$C$4:$C$368=A15)*'Task Plan'!$H$4:$H$368*'Task Plan'!$L$4:$L$368) -> 0 | D15: =IFERROR(C15/B15,0) -> 0 | E15: =COUNTIF('Task Plan'!$C:$C,A15) -> 50 | F15: =COUNTIFS('Task Plan'!$C:$C,A15,'Task Plan'!$K:$K,"Completed") -> 0
A16: 2 - SCD Type 2 | B16: =SUMIF('Task Plan'!$C:$C,A16,'Task Plan'!$H:$H) -> 37.5 | C16: =SUMPRODUCT(('Task Plan'!$C$4:$C$368=A16)*'Task Plan'!$H$4:$H$368*'Task Plan'!$L$4:$L$368) -> 0 | D16: =IFERROR(C16/B16,0) -> 0 | E16: =COUNTIF('Task Plan'!$C:$C,A16) -> 40 | F16: =COUNTIFS('Task Plan'!$C:$C,A16,'Task Plan'!$K:$K,"Completed") -> 0
A17: 3 - Revenue Analytics | B17: =SUMIF('Task Plan'!$C:$C,A17,'Task Plan'!$H:$H) -> 32 | C17: =SUMPRODUCT(('Task Plan'!$C$4:$C$368=A17)*'Task Plan'!$H$4:$H$368*'Task Plan'!$L$4:$L$368) -> 0 | D17: =IFERROR(C17/B17,0) -> 0 | E17: =COUNTIF('Task Plan'!$C:$C,A17) -> 35 | F17: =COUNTIFS('Task Plan'!$C:$C,A17,'Task Plan'!$K:$K,"Completed") -> 0
A18: 4 - Deduplication | B18: =SUMIF('Task Plan'!$C:$C,A18,'Task Plan'!$H:$H) -> 28 | C18: =SUMPRODUCT(('Task Plan'!$C$4:$C$368=A18)*'Task Plan'!$H$4:$H$368*'Task Plan'!$L$4:$L$368) -> 0 | D18: =IFERROR(C18/B18,0) -> 0 | E18: =COUNTIF('Task Plan'!$C:$C,A18) -> 30 | F18: =COUNTIFS('Task Plan'!$C:$C,A18,'Task Plan'!$K:$K,"Completed") -> 0
A19: 5 - Delivery Delay | B19: =SUMIF('Task Plan'!$C:$C,A19,'Task Plan'!$H:$H) -> 29 | C19: =SUMPRODUCT(('Task Plan'!$C$4:$C$368=A19)*'Task Plan'!$H$4:$H$368*'Task Plan'!$L$4:$L$368) -> 0 | D19: =IFERROR(C19/B19,0) -> 0 | E19: =COUNTIF('Task Plan'!$C:$C,A19) -> 30 | F19: =COUNTIFS('Task Plan'!$C:$C,A19,'Task Plan'!$K:$K,"Completed") -> 0
A20: 6 - Top Customers | B20: =SUMIF('Task Plan'!$C:$C,A20,'Task Plan'!$H:$H) -> 22 | C20: =SUMPRODUCT(('Task Plan'!$C$4:$C$368=A20)*'Task Plan'!$H$4:$H$368*'Task Plan'!$L$4:$L$368) -> 0 | D20: =IFERROR(C20/B20,0) -> 0 | E20: =COUNTIF('Task Plan'!$C:$C,A20) -> 25 | F20: =COUNTIFS('Task Plan'!$C:$C,A20,'Task Plan'!$K:$K,"Completed") -> 0
A21: 7 - Incremental Load | B21: =SUMIF('Task Plan'!$C:$C,A21,'Task Plan'!$H:$H) -> 44 | C21: =SUMPRODUCT(('Task Plan'!$C$4:$C$368=A21)*'Task Plan'!$H$4:$H$368*'Task Plan'!$L$4:$L$368) -> 0 | D21: =IFERROR(C21/B21,0) -> 0 | E21: =COUNTIF('Task Plan'!$C:$C,A21) -> 45 | F21: =COUNTIFS('Task Plan'!$C:$C,A21,'Task Plan'!$K:$K,"Completed") -> 0
A22: 8 - Performance Tuning | B22: =SUMIF('Task Plan'!$C:$C,A22,'Task Plan'!$H:$H) -> 43.5 | C22: =SUMPRODUCT(('Task Plan'!$C$4:$C$368=A22)*'Task Plan'!$H$4:$H$368*'Task Plan'!$L$4:$L$368) -> 0 | D22: =IFERROR(C22/B22,0) -> 0 | E22: =COUNTIF('Task Plan'!$C:$C,A22) -> 45 | F22: =COUNTIFS('Task Plan'!$C:$C,A22,'Task Plan'!$K:$K,"Completed") -> 0
A23: 9 - Reconciliation & RCA | B23: =SUMIF('Task Plan'!$C:$C,A23,'Task Plan'!$H:$H) -> 28.5 | C23: =SUMPRODUCT(('Task Plan'!$C$4:$C$368=A23)*'Task Plan'!$H$4:$H$368*'Task Plan'!$L$4:$L$368) -> 0 | D23: =IFERROR(C23/B23,0) -> 0 | E23: =COUNTIF('Task Plan'!$C:$C,A23) -> 30 | F23: =COUNTIFS('Task Plan'!$C:$C,A23,'Task Plan'!$K:$K,"Completed") -> 0
A24: 10 - Packaging & Portfolio | B24: =SUMIF('Task Plan'!$C:$C,A24,'Task Plan'!$H:$H) -> 32 | C24: =SUMPRODUCT(('Task Plan'!$C$4:$C$368=A24)*'Task Plan'!$H$4:$H$368*'Task Plan'!$L$4:$L$368) -> 0 | D24: =IFERROR(C24/B24,0) -> 0 | E24: =COUNTIF('Task Plan'!$C:$C,A24) -> 35 | F24: =COUNTIFS('Task Plan'!$C:$C,A24,'Task Plan'!$K:$K,"Completed") -> 0
A28: Test Status | B28: Count
A29: Not Run | B29: =COUNTIF('Test Cases'!$I:$I,A29) -> 88
A30: Passed | B30: =COUNTIF('Test Cases'!$I:$I,A30) -> 0
A31: Failed | B31: =COUNTIF('Test Cases'!$I:$I,A31) -> 0
A32: Blocked | B32: =COUNTIF('Test Cases'!$I:$I,A32) -> 0

Sheet Risks & Decisions
A1: Risks, Assumptions and Design Decisions
A3: ID | B3: Type | C3: Phase | D3: Item | E3: Impact | F3: Mitigation / Decision | G3: Owner | H3: Status | I3: Review Notes
A4: R-001 | B4: Risk | C4: 1 - Warehouse Modeling | D4: Order source lacks OrderLineNumber | E4: Cannot guarantee one row per line when product repeats | F4: Create deterministic line identifier from source; do not assume OrderID + ProductID is always unique. | G4: Mukesh | H4: Open
A5: R-002 | B5: Risk | C5: 3 - Revenue Analytics | D5: Revenue definition is ambiguous | E5: Different reports can show different totals | F5: Create a signed metric definition including discounts, cancellations, tax, currency and recognition date. | G5: Mukesh | H5: Open
A6: R-003 | B6: Risk | C6: 7 - Incremental Load | D6: Timestamp precision or timezone mismatch | E6: Rows may be missed or duplicated | F6: Normalize timezone, use bounded windows and test exact-boundary timestamps. | G6: Mukesh | H6: Open
A7: R-004 | B7: Risk | C7: 8 - Performance Tuning | D7: Synthetic volume too small | E7: Index/partition findings may not represent scale | F7: Generate sufficient distribution and compare plans and logical reads; label results as local benchmark. | G7: Mukesh | H7: Open
A8: R-005 | B8: Risk | C8: 2 - SCD Type 2 | D8: Concurrent updates create two current versions | E8: History becomes invalid | F8: Use transactional logic and current-row uniqueness protection. | G8: Mukesh | H8: Open
A9: A-001 | B9: Assumption | C9: All | D9: Practice data is synthetic | E9: Cannot claim real client volume or production impact | F9: Clearly label project and metrics as self-directed portfolio results. | G9: Mukesh | H9: Accepted
A10: D-001 | B10: Decision | C10: 5 - Delivery Delay | D10: Delay buckets use 16+ final bucket | E10: Avoids overlap between 8-15 and 15+ | F10: Use CASE boundaries: 0-3, 4-7, 8-15, 16+. | G10: Mukesh | H10: Accepted
A11: D-002 | B11: Decision | C11: 1 - Warehouse Modeling | D11: Facts will use surrogate dimension keys | E11: Supports history and source-system independence | F11: Retain source keys as audit/business identifiers. | G11: Mukesh | H11: Accepted

Sheet Resume Notes
A1: Portfolio and Resume Notes
A3: Recommended Project Title | B3: Global Logistics SQL Data Warehouse | Self-Directed Portfolio Project
A5: Use after implementation
A6: • Designed a SQL Server star schema for logistics order and shipment analytics, defining fact grains, surrogate-key dimensions, role-playing dates, audit columns and unknown-member handling.
A7: • Implemented SCD Type 2 customer history with null-safe change detection, non-overlapping effective periods, current-version enforcement and idempotent rerun behavior.
A8: • Built reusable SQL analytics for monthly revenue, prior-period growth, country-level customer ranking and delivery-delay classification using window functions and dimensional joins.
A9: • Developed restartable incremental-load controls using bounded watermarks, batch auditing, reconciliation metrics, reject handling and failure-recovery tests.
A10: • Benchmarked and tuned reporting queries using execution plans, logical reads, sargable predicates, indexing and aggregate-table design; report only the improvements actually measured in your environment.
A13: Do Not Claim
A14: • Do not call it a client project unless it was delivered for a real client.
A15: • Do not claim 500 million production rows unless you actually tested that volume.
A16: • Do not claim a percentage performance improvement until your before/after evidence supports it.
A17: • Do not list a technology that is not present in your implementation repository.
A20: Interview Walkthrough
... A27: 7. Limitations and what you would change at production scale
